<?xml version="1.0" ?>
<robot name="Franka_Emika_Panda" version="1.0">

    <link name="link0">
        <visual>
            <geometry>
                <mesh filename="package://franka_description/meshes/visual/link0.stl" />
            </geometry>
			<material name="white"/>
        </visual>
        <collision>
            <geometry>
                <mesh filename="package://franka_description/meshes/collision/link0.stl" />
            </geometry>
        </collision>
    </link>
	
	<link name="s_frame" />
	
	<joint name="s_frame" type="fixed">
		<parent link="link0"/>
		<child link="s_frame"/>
		<origin rpy="0.0 0.0 0.0" xyz="0.0 0.0 0.0"/>
	</joint>
	
    <link name="link1">
        <visual>
            <geometry>
                <mesh filename="package://franka_description/meshes/visual/link1.stl" />
            </geometry>
			<material name="black"/>
        </visual>
        <collision>
            <geometry>
                <mesh filename="package://franka_description/meshes/collision/link1.stl" />
            </geometry>
        </collision>
    </link>
	
    <joint name="joint1" type="revolute">
        <safety_controller k_position="100.0" k_velocity="40.0" soft_lower_limit="-2.8973" soft_upper_limit="2.8973" />
        <origin rpy="0 0 0" xyz="0 0 0.333" />
        <parent link="link0" />
        <child link="link1" />
        <axis xyz="0 0 1" />
        <limit effort="87" lower="-2.8973" upper="2.8973" velocity="2.1750" />
    </joint>
	
    <link name="link2">
        <visual>
            <geometry>
                <mesh filename="package://franka_description/meshes/visual/link2.stl" />
            </geometry>
			<material name="white"/>
        </visual>
        <collision>
            <geometry>
                <mesh filename="package://franka_description/meshes/collision/link2.stl" />
            </geometry>
        </collision>
    </link>
	
    <joint name="joint2" type="revolute">
        <safety_controller k_position="100.0" k_velocity="40.0" soft_lower_limit="-1.7628" soft_upper_limit="1.7628" />
        <origin rpy="-1.57079632679 0 0" xyz="0 0 0" />
        <parent link="link1" />
        <child link="link2" />
        <axis xyz="0 0 1" />
        <limit effort="87" lower="-1.7628" upper="1.7628" velocity="2.1750" />
    </joint>
	
    <link name="link3">
        <visual>
            <geometry>
                <mesh filename="package://franka_description/meshes/visual/link3.stl" />
            </geometry>
			<material name="black"/>
        </visual>
        <collision>
            <geometry>
                <mesh filename="package://franka_description/meshes/collision/link3.stl" />
            </geometry>
        </collision>
    </link>
	
    <joint name="joint3" type="revolute">
        <safety_controller k_position="100.0" k_velocity="40.0" soft_lower_limit="-2.8973" soft_upper_limit="2.8973" />
        <origin rpy="1.57079632679 0 0" xyz="0 -0.316 0" />
        <parent link="link2" />
        <child link="link3" />
        <axis xyz="0 0 1" />
        <limit effort="87" lower="-2.8973" upper="2.8973" velocity="2.1750" />
    </joint>
	
    <link name="link4">
        <visual>
            <geometry>
                <mesh filename="package://franka_description/meshes/visual/link4.stl" />
            </geometry>
			<material name="white"/>
        </visual>
        <collision>
            <geometry>
                <mesh filename="package://franka_description/meshes/collision/link4.stl" />
            </geometry>
        </collision>
    </link>
	
    <joint name="joint4" type="revolute">
        <safety_controller k_position="100.0" k_velocity="40.0" soft_lower_limit="-3.0718" soft_upper_limit="-0.0698" />
        <origin rpy="1.57079632679 0 0" xyz="0.0825 0 0" />
        <parent link="link3" />
        <child link="link4" />
        <axis xyz="0 0 1" />
        <limit effort="87" lower="-3.0718" upper="-0.0698" velocity="2.1750" />
    </joint>
	
    <link name="link5">
        <visual>
            <geometry>
                <mesh filename="package://franka_description/meshes/visual/link5.stl" />
            </geometry>
			<material name="black"/>
        </visual>
        <collision>
            <geometry>
                <mesh filename="package://franka_description/meshes/collision/link5.stl" />
            </geometry>
        </collision>
    </link>
	
    <joint name="joint5" type="revolute">
        <safety_controller k_position="100.0" k_velocity="40.0" soft_lower_limit="-2.8973" soft_upper_limit="2.8973" />
        <origin rpy="-1.57079632679 0 0" xyz="-0.0825 0.384 0" />
        <parent link="link4" />
        <child link="link5" />
        <axis xyz="0 0 1" />
        <limit effort="12" lower="-2.8973" upper="2.8973" velocity="2.6100" />
    </joint>
	
    <link name="link6">
        <visual>
            <geometry>
                <mesh filename="package://franka_description/meshes/visual/link6.stl" />
            </geometry>
			<material name="white"/>
        </visual>
        <collision>
            <geometry>
                <mesh filename="package://franka_description/meshes/collision/link6.stl" />
            </geometry>
        </collision>
    </link>
	
    <joint name="joint6" type="revolute">
        <safety_controller k_position="100.0" k_velocity="40.0" soft_lower_limit="-0.0175" soft_upper_limit="3.7525" />
        <origin rpy="1.57079632679 0 0" xyz="0 0 0" />
        <parent link="link5" />
        <child link="link6" />
        <axis xyz="0 0 1" />
        <limit effort="12" lower="-0.0175" upper="3.7525" velocity="2.6100" />
    </joint>
	
    <link name="link7">
        <visual>
            <geometry>
                <mesh filename="package://franka_description/meshes/visual/link7.stl" />
            </geometry>
			<material name="black"/>
        </visual>
        <collision>
            <geometry>
                <mesh filename="package://franka_description/meshes/collision/link7.stl" />
            </geometry>
        </collision>
    </link>
	
    <joint name="joint7" type="revolute">
        <safety_controller k_position="100.0" k_velocity="40.0" soft_lower_limit="-2.8973" soft_upper_limit="2.8973" />
        <origin rpy="1.57079632679 0 0" xyz="0.088 0 0" />
        <parent link="link6" />
        <child link="link7" />
        <axis xyz="0 0 1" />
        <limit effort="12" lower="-2.8973" upper="2.8973" velocity="2.6100" />
    </joint>
	
    <link name="b_frame" />
	
    <joint name="b_frame" type="fixed">
        <origin rpy="0 0 0" xyz="0 0 0.107" />
        <parent link="link7" />
        <child link="b_frame" />
        <axis xyz="0 0 0" />
    </joint>
	
	<material name="white">
		<color rgba="0.8 0.8 0.8 1"/>
	</material>
	
	<material name="black">
		<color rgba="0.2 0.2 0.2 1"/>
	</material>
	
</robot>
